<?xml version="1.0" encoding="utf-8"?>
<!-- This URDF was automatically created by SolidWorks to URDF Exporter! Originally created by Stephen Brawner (brawner@gmail.com) 
     Commit Version: 1.6.0-4-g7f85cfe  Build Version: 1.6.7995.38578
     For more information, please see http://wiki.ros.org/sw_urdf_exporter -->
<robot
  name="robot_arm_urdf">
  
  <link name="world"/>
  
  <link
    name="base_link">
    <inertial>
      <origin
        xyz="0.146303583389375 0.0227364363233699 0.0786183231131826"
        rpy="0 0 0" />
      <mass
        value="2.27847589927695" />
      <inertia
        ixx="0.00380444742254977"
        ixy="-0.000206188903864419"
        ixz="0.000150989469734131"
        iyy="0.00486443002009746"
        iyz="1.9405372408666E-05"
        izz="0.00720649909693205" />
    </inertial>
    <visual>
      <origin
        xyz="0 0 0"
        rpy="0 0 0" />
      <geometry>
        <mesh
          filename="package://robot_arm_urdf/meshes/base_link.STL" />
      </geometry>
      <material
        name="">
        <color
          rgba="0.752941176470588 0.752941176470588 0.752941176470588 1" />
      </material>
    </visual>
    <collision>
      <origin
        xyz="0 0 0"
        rpy="0 0 0" />
      <geometry>
        <mesh
          filename="package://robot_arm_urdf/meshes/base_link.STL" />
      </geometry>
    </collision>
  </link>
  
  <joint name="base_joint" type="fixed">
  	<parent link="world"/>
  	<child link="base_link"/>
  	<origin rpy="0 0 0" xyz="0.0 0.0 0.25"/>
  </joint>
  
  <link
    name="link_1">
    <inertial>
      <origin
        xyz="0.0306447925880698 0.281344566727743 0.372206162482047"
        rpy="0 0 0" />
      <mass
        value="0.641883744293896" />
      <inertia
        ixx="0.000465537868722206"
        ixy="2.92544171696999E-05"
        ixz="2.03341844754776E-05"
        iyy="0.000617295838132801"
        iyz="-3.98067161000968E-06"
        izz="0.000626361475668464" />
    </inertial>
    <visual>
      <origin
        xyz="0 0 0"
        rpy="0 0 0" />
      <geometry>
        <mesh
          filename="package://robot_arm_urdf/meshes/link_1.STL" />
      </geometry>
      <material
        name="">
        <color
          rgba="0.752941176470588 0.752941176470588 0.752941176470588 1" />
      </material>
    </visual>
    <collision>
      <origin
        xyz="0 0 0"
        rpy="0 0 0" />
      <geometry>
        <mesh
          filename="package://robot_arm_urdf/meshes/link_1.STL" />
      </geometry>
    </collision>
  </link>
  <joint
    name="joint_1"
    type="revolute">
    <origin
      xyz="0.004244 0.37679 -0.077856"
      rpy="1.5708 0 0" />
    <parent
      link="base_link" />
    <child
      link="link_1" />
    <axis
      xyz="0 1 0" />
    <limit
      lower="-3.142"
      upper="3.142"
      effort="28.35"
      velocity="5.24" />
  </joint>
  <link
    name="link_2">
    <inertial>
      <origin
        xyz="0.00995410909543785 0.173905303533361 0.0632176576099199"
        rpy="0 0 0" />
      <mass
        value="0.394669428659782" />
      <inertia
        ixx="0.00201544140173863"
        ixy="-4.81655903692797E-07"
        ixz="-5.89755045158386E-06"
        iyy="0.00014684046202116"
        iyz="1.0488729854379E-07"
        izz="0.00197252279397421" />
    </inertial>
    <visual>
      <origin
        xyz="0 0 0"
        rpy="0 0 0" />
      <geometry>
        <mesh
          filename="package://robot_arm_urdf/meshes/link_2.STL" />
      </geometry>
      <material
        name="">
        <color
          rgba="0.752941176470588 0.752941176470588 0.752941176470588 1" />
      </material>
    </visual>
    <collision>
      <origin
        xyz="0 0 0"
        rpy="0 0 0" />
      <geometry>
        <mesh
          filename="package://robot_arm_urdf/meshes/link_2.STL" />
      </geometry>
    </collision>
  </link>
  <joint
    name="joint_2"
    type="revolute">
    <origin
      xyz="-0.0129136150732728 0.308337646724069 0.307358400547654"
      rpy="0 0 0" />
    <parent
      link="link_1" />
    <child
      link="link_2" />
    <axis
      xyz="-0.125391445630158 0 -0.992107345685324" />
    <limit
      lower="-1.57"
      upper="1.57"
      effort="28.35"
      velocity="5.24" />
  </joint>
  <link
    name="link_3">
    <inertial>
      <origin
        xyz="-0.101730833124941 -0.00013569897650012 0.112485387666801"
        rpy="0 0 0" />
      <mass
        value="0.259256412516919" />
      <inertia
        ixx="8.82055214106673E-05"
        ixy="1.91288092550191E-08"
        ixz="0.000147246406091982"
        iyy="0.0012487740196317"
        iyz="5.73285944186787E-08"
        izz="0.0012348363247349" />
    </inertial>
    <visual>
      <origin
        xyz="0 0 0"
        rpy="0 0 0" />
      <geometry>
        <mesh
          filename="package://robot_arm_urdf/meshes/link_3.STL" />
      </geometry>
      <material
        name="">
        <color
          rgba="0.752941176470588 0.752941176470588 0.752941176470588 1" />
      </material>
    </visual>
    <collision>
      <origin
        xyz="0 0 0"
        rpy="0 0 0" />
      <geometry>
        <mesh
          filename="package://robot_arm_urdf/meshes/link_3.STL" />
      </geometry>
    </collision>
  </link>
  <joint
    name="joint_3"
    type="revolute">
    <origin
      xyz="-0.0040937973882068 0.406399999999999 -0.0323904588559681"
      rpy="0 0 0" />
    <parent
      link="link_2" />
    <child
      link="link_3" />
    <axis
      xyz="-0.125391445630158 0 -0.992107345685324" />
    <limit
      lower="-1"
      upper="3.14"
      effort="7.85"
      velocity="6.54" />
  </joint>
  <link
    name="link_4">
    <inertial>
      <origin
        xyz="0.00956075507296156 0.028864624504545 0.0735538720173586"
        rpy="0 0 0" />
      <mass
        value="0.18731544221453" />
      <inertia
        ixx="0.000131172951702039"
        ixy="4.79991337558464E-09"
        ixz="-3.82564484824128E-06"
        iyy="0.000133438325492828"
        iyz="1.72597973055121E-08"
        izz="0.000105908438964448" />
    </inertial>
    <visual>
      <origin
        xyz="0 0 0"
        rpy="0 0 0" />
      <geometry>
        <mesh
          filename="package://robot_arm_urdf/meshes/link_4.STL" />
      </geometry>
      <material
        name="">
        <color
          rgba="0.752941176470588 0.752941176470588 0.752941176470588 1" />
      </material>
    </visual>
    <collision>
      <origin
        xyz="0 0 0"
        rpy="0 0 0" />
      <geometry>
        <mesh
          filename="package://robot_arm_urdf/meshes/link_4.STL" />
      </geometry>
    </collision>
  </link>
  <joint
    name="joint_4"
    type="revolute">
    <origin
      xyz="-0.344415980373364 0 0.0713450468234001"
      rpy="0 0 0" />
    <parent
      link="link_3" />
    <child
      link="link_4" />
    <axis
      xyz="-0.125391445630158 0 -0.992107345685324" />
    <limit
      lower="-3.14"
      upper="0"
      effort="2.45"
      velocity="8.08" />
  </joint>
  <link
    name="link_5">
    <inertial>
      <origin
        xyz="-4.27844132344646E-09 0.013259123530174 2.67440514178929E-09"
        rpy="0 0 0" />
      <mass
        value="0.00352439273827263" />
      <inertia
        ixx="2.30460116989414E-07"
        ixy="4.50680847413183E-13"
        ixz="4.85236076885767E-12"
        iyy="3.99508652333463E-07"
        iyz="5.01163318609839E-13"
        izz="2.30445970855517E-07" />
    </inertial>
    <visual>
      <origin
        xyz="0 0 0"
        rpy="0 0 0" />
      <geometry>
        <mesh
          filename="package://robot_arm_urdf/meshes/link_5.STL" />
      </geometry>
      <material
        name="">
        <color
          rgba="0.752941176470588 0.752941176470588 0.752941176470588 1" />
      </material>
    </visual>
    <collision>
      <origin
        xyz="0 0 0"
        rpy="0 0 0" />
      <geometry>
        <mesh
          filename="package://robot_arm_urdf/meshes/link_5.STL" />
      </geometry>
    </collision>
  </link>
  <joint
    name="joint_5"
    type="revolute">
    <origin
      xyz="0.00886960764909822 0.0715224872569122 0.0701770591910485"
      rpy="0 0 0" />
    <parent
      link="link_4" />
    <child
      link="link_5" />
    <axis
      xyz="0 -1 0" />
    <limit
      lower="-3.14"
      upper="3.14"
      effort="2.45"
      velocity="8.08" />
  </joint>
  
  <transmission name="link_1_trans">
  	<type>transmission_interface/SimpleTransmission</type>
  	<joint name="joint_1">
  		<hardwareInterface>hardware_interface/PositionJointInterface</hardwareInterface>
  	</joint>
  	<actuator name="link_1_motor">
  		<hardwareInterface>hardware_interface/PositionJointInterface</hardwareInterface>
  		<mechanicalReduction>1</mechanicalReduction>
  	</actuator>
  </transmission>
  
  <transmission name="link_2_trans">
  	<type>transmission_interface/SimpleTransmission</type>
  	<joint name="joint_2">
  		<hardwareInterface>hardware_interface/PositionJointInterface</hardwareInterface>
  	</joint>
  	<actuator name="link_2_motor">
  		<hardwareInterface>hardware_interface/PositionJointInterface</hardwareInterface>
  		<mechanicalReduction>1</mechanicalReduction>
  	</actuator>
  </transmission>
  
  <transmission name="link_3_trans">
  	<type>transmission_interface/SimpleTransmission</type>
  	<joint name="joint_3">
  		<hardwareInterface>hardware_interface/PositionJointInterface</hardwareInterface>
  	</joint>
  	<actuator name="link_3_motor">
  		<hardwareInterface>hardware_interface/PositionJointInterface</hardwareInterface>
  		<mechanicalReduction>1</mechanicalReduction>
  	</actuator>
  </transmission>
  
  <transmission name="link_4_trans">
  	<type>transmission_interface/SimpleTransmission</type>
  	<joint name="joint_4">
  		<hardwareInterface>hardware_interface/PositionJointInterface</hardwareInterface>
  	</joint>
  	<actuator name="link_4_motor">
  		<hardwareInterface>hardware_interface/PositionJointInterface</hardwareInterface>
  		<mechanicalReduction>1</mechanicalReduction>
  	</actuator>
  </transmission>
  
  <transmission name="link_5_trans">
  	<type>transmission_interface/SimpleTransmission</type>
  	<joint name="joint_5">
  		<hardwareInterface>hardware_interface/PositionJointInterface</hardwareInterface>
  	</joint>
  	<actuator name="link_5_motor">
  		<hardwareInterface>hardware_interface/PositionJointInterface</hardwareInterface>
  		<mechanicalReduction>1</mechanicalReduction>
  	</actuator>
  </transmission>
  
  <gazebo>
  	<plugin name="control" filename="libgazebo_ros_control.so">
  		<robotNamespace>/</robotNamespace>
  	</plugin>
  </gazebo>
  
  <gazebo reference="link_1">
  	<selfCollide>true</selfCollide>
  </gazebo>
  
  <gazebo reference="link_2">
  	<selfCollide>true</selfCollide>
  </gazebo>
  
  <gazebo reference="link_3">
  	<selfCollide>true</selfCollide>
  </gazebo>
  
  <gazebo reference="link_4">
  	<selfCollide>true</selfCollide>
  </gazebo>
  
  <gazebo reference="link_5">
  	<selfCollide>true</selfCollide>
  </gazebo>
  
</robot>
