<?xml version="1.0" encoding="utf-8"?>
<!-- This URDF was automatically created by SolidWorks to URDF Exporter! Originally created by Stephen Brawner (brawner@gmail.com) 
     Commit Version: 1.6.0-4-g7f85cfe  Build Version: 1.6.7995.38578
     For more information, please see http://wiki.ros.org/sw_urdf_exporter -->
<robot
  name="robot_arm_urdf">

  <link name="world"/>

  <link
    name="base_link">
    <inertial>
      <origin
        xyz="-0.00066697 -7.2955E-05 0.11391"
        rpy="0 0 0" />
      <mass
        value="1.2708" />
      <inertia
        ixx="0.0025837"
        ixy="-1.2489E-07"
        ixz="-3.2925E-07"
        iyy="0.0025874"
        iyz="-4.1069E-08"
        izz="0.0043243" />
    </inertial>
    <visual>
      <origin
        xyz="0 0 0"
        rpy="0 0 0" />
      <geometry>
        <mesh
          filename="package://robot_arm_urdf/meshes/base_link.STL" />
      </geometry>
      <material
        name="">
        <color
          rgba="0.75294 0.75294 0.75294 1" />
      </material>
    </visual>
    <collision>
      <origin
        xyz="0 0 0"
        rpy="0 0 0" />
      <geometry>
        <mesh
          filename="package://robot_arm_urdf/meshes/base_link.STL" />
      </geometry>
    </collision>
  </link>

  <joint name="base_joint" type="fixed">
  	<parent link="world"/>
  	<child link="base_link"/>
  	<origin rpy="0 0 0" xyz="0.0 0.0 0.25"/>
  </joint>

  <link
    name="link_1">
    <inertial>
      <origin
        xyz="-1.3692E-05 -1.7969E-05 0.0089223"
        rpy="0 0 0" />
      <mass
        value="0.10142" />
      <inertia
        ixx="8.687E-05"
        ixy="8.9807E-08"
        ixz="-3.7136E-09"
        iyy="8.6652E-05"
        iyz="-4.8736E-09"
        izz="0.00017129" />
    </inertial>
    <visual>
      <origin
        xyz="0 0 0"
        rpy="0 0 0" />
      <geometry>
        <mesh
          filename="package://robot_arm_urdf/meshes/link_1.STL" />
      </geometry>
      <material
        name="">
        <color
          rgba="0.75294 0.75294 0.75294 1" />
      </material>
    </visual>
    <collision>
      <origin
        xyz="0 0 0"
        rpy="0 0 0" />
      <geometry>
        <mesh
          filename="package://robot_arm_urdf/meshes/link_1.STL" />
      </geometry>
    </collision>
  </link>
  <joint
    name="joint_1"
    type="revolute">
    <origin
      xyz="0 0 0.15678"
      rpy="0 0 0" />
    <parent
      link="base_link" />
    <child
      link="link_1" />
    <axis
      xyz="0 0 1" />
    <limit
      lower="-3.142"
      upper="3.142"
      effort="28.35"
      velocity="5.24" />
  </joint>
  <link
    name="link_2">
    <inertial>
      <origin
        xyz="0.001181 0.0061963 0.17391"
        rpy="0 0 0" />
      <mass
        value="0.39467" />
      <inertia
        ixx="0.0020154"
        ixy="5.8976E-06"
        ixz="-4.8166E-07"
        iyy="0.0019725"
        iyz="-1.0489E-07"
        izz="0.00014684" />
    </inertial>
    <visual>
      <origin
        xyz="0 0 0"
        rpy="0 0 0" />
      <geometry>
        <mesh
          filename="package://robot_arm_urdf/meshes/link_2.STL" />
      </geometry>
      <material
        name="">
        <color
          rgba="0.75294 0.75294 0.75294 1" />
      </material>
    </visual>
    <collision>
      <origin
        xyz="0 0 0"
        rpy="0 0 0" />
      <geometry>
        <mesh
          filename="package://robot_arm_urdf/meshes/link_2.STL" />
      </geometry>
    </collision>
  </link>
  <joint
    name="joint_2"
    type="revolute">
    <origin
      xyz="0.00010358 1.3092E-05 0.0737"
      rpy="0 0 0" />
    <parent
      link="link_1" />
    <child
      link="link_2" />
    <axis
      xyz="-0.12539 0.99211 0" />
    <limit
      lower="-1.57"
      upper="1.57"
      effort="28.35"
      velocity="5.24" />
  </joint>
  <link
    name="link_3">
    <inertial>
      <origin
        xyz="-0.1146 -0.010681 -0.0001357"
        rpy="0 0 0" />
      <mass
        value="0.25926" />
      <inertia
        ixx="8.8206E-05"
        ixy="-0.00014725"
        ixz="1.9129E-08"
        iyy="0.0012348"
        iyz="-5.7329E-08"
        izz="0.0012488" />
    </inertial>
    <visual>
      <origin
        xyz="0 0 0"
        rpy="0 0 0" />
      <geometry>
        <mesh
          filename="package://robot_arm_urdf/meshes/link_3.STL" />
      </geometry>
      <material
        name="">
        <color
          rgba="0.75294 0.75294 0.75294 1" />
      </material>
    </visual>
    <collision>
      <origin
        xyz="0 0 0"
        rpy="0 0 0" />
      <geometry>
        <mesh
          filename="package://robot_arm_urdf/meshes/link_3.STL" />
      </geometry>
    </collision>
  </link>
  <joint
    name="joint_3"
    type="revolute">
    <origin
      xyz="0 0 0.4064"
      rpy="0 0 0" />
    <parent
      link="link_2" />
    <child
      link="link_3" />
    <axis
      xyz="0.12539 -0.99211 0" />
    <limit
      lower="-3.14"
      upper="1"
      effort="7.85"
      velocity="6.54" />
  </joint>
  <link
    name="link_4">
    <inertial>
      <origin
        xyz="0.00069115 -0.0033768 0.028865"
        rpy="0 0 0" />
      <mass
        value="0.18732" />
      <inertia
        ixx="0.00013117"
        ixy="3.8256E-06"
        ixz="4.7999E-09"
        iyy="0.00010591"
        iyz="-1.726E-08"
        izz="0.00013344" />
    </inertial>
    <visual>
      <origin
        xyz="0 0 0"
        rpy="0 0 0" />
      <geometry>
        <mesh
          filename="package://robot_arm_urdf/meshes/link_4.STL" />
      </geometry>
      <material
        name="">
        <color
          rgba="0.75294 0.75294 0.75294 1" />
      </material>
    </visual>
    <collision>
      <origin
        xyz="0 0 0"
        rpy="0 0 0" />
      <geometry>
        <mesh
          filename="package://robot_arm_urdf/meshes/link_4.STL" />
      </geometry>
    </collision>
  </link>
  <joint
    name="joint_4"
    type="revolute">
    <origin
      xyz="-0.34841 -0.039718 0"
      rpy="0 0 0" />
    <parent
      link="link_3" />
    <child
      link="link_4" />
    <axis
      xyz="-0.12539 0.99211 0" />
    <limit
      lower="-3.14"
      upper="0"
      effort="2.45"
      velocity="8.08" />
  </joint>
  <link
    name="link_5">
    <inertial>
      <origin
        xyz="-4.2785E-09 -2.6744E-09 0.0075841"
        rpy="0 0 0" />
      <mass
        value="0.0035244" />
      <inertia
        ixx="2.3046E-07"
        ixy="-4.8524E-12"
        ixz="4.5068E-13"
        iyy="2.3045E-07"
        iyz="-5.0116E-13"
        izz="3.9951E-07" />
    </inertial>
    <visual>
      <origin
        xyz="0 0 0"
        rpy="0 0 0" />
      <geometry>
        <mesh
          filename="package://robot_arm_urdf/meshes/link_5.STL" />
      </geometry>
      <material
        name="">
        <color
          rgba="0.75294 0.75294 0.75294 1" />
      </material>
    </visual>
    <collision>
      <origin
        xyz="0 0 0"
        rpy="0 0 0" />
      <geometry>
        <mesh
          filename="package://robot_arm_urdf/meshes/link_5.STL" />
      </geometry>
    </collision>
  </link>
  <joint
    name="joint_5"
    type="revolute">
    <origin
      xyz="0 0 0.077198"
      rpy="0 0 0" />
    <parent
      link="link_4" />
    <child
      link="link_5" />
    <axis
      xyz="0 0 -1" />
    <limit
      lower="-3.14"
      upper="3.14"
      effort="2.45"
      velocity="8.08" />
  </joint>

  <transmission name="link_1_trans">
  	<type>transmission_interface/SimpleTransmission</type>
  	<joint name="joint_1">
  		<hardwareInterface>hardware_interface/PositionJointInterface</hardwareInterface>
  	</joint>
  	<actuator name="link_1_motor">
  		<hardwareInterface>hardware_interface/PositionJointInterface</hardwareInterface>
  		<mechanicalReduction>1</mechanicalReduction>
  	</actuator>
  </transmission>
  
  <transmission name="link_2_trans">
  	<type>transmission_interface/SimpleTransmission</type>
  	<joint name="joint_2">
  		<hardwareInterface>hardware_interface/PositionJointInterface</hardwareInterface>
  	</joint>
  	<actuator name="link_2_motor">
  		<hardwareInterface>hardware_interface/PositionJointInterface</hardwareInterface>
  		<mechanicalReduction>1</mechanicalReduction>
  	</actuator>
  </transmission>
  
  <transmission name="link_3_trans">
  	<type>transmission_interface/SimpleTransmission</type>
  	<joint name="joint_3">
  		<hardwareInterface>hardware_interface/PositionJointInterface</hardwareInterface>
  	</joint>
  	<actuator name="link_3_motor">
  		<hardwareInterface>hardware_interface/PositionJointInterface</hardwareInterface>
  		<mechanicalReduction>1</mechanicalReduction>
  	</actuator>
  </transmission>
  
  <transmission name="link_4_trans">
  	<type>transmission_interface/SimpleTransmission</type>
  	<joint name="joint_4">
  		<hardwareInterface>hardware_interface/PositionJointInterface</hardwareInterface>
  	</joint>
  	<actuator name="link_4_motor">
  		<hardwareInterface>hardware_interface/PositionJointInterface</hardwareInterface>
  		<mechanicalReduction>1</mechanicalReduction>
  	</actuator>
  </transmission>
  
  <transmission name="link_5_trans">
  	<type>transmission_interface/SimpleTransmission</type>
  	<joint name="joint_5">
  		<hardwareInterface>hardware_interface/PositionJointInterface</hardwareInterface>
  	</joint>
  	<actuator name="link_5_motor">
  		<hardwareInterface>hardware_interface/PositionJointInterface</hardwareInterface>
  		<mechanicalReduction>1</mechanicalReduction>
  	</actuator>
  </transmission>
  
  <gazebo>
  	<plugin name="control" filename="libgazebo_ros_control.so">
  		<robotNamespace>/</robotNamespace>
  	</plugin>
  </gazebo>
  
  <gazebo reference="link_1">
  	<selfCollide>true</selfCollide>
  </gazebo>
  
  <gazebo reference="link_2">
  	<selfCollide>true</selfCollide>
  </gazebo>
  
  <gazebo reference="link_3">
  	<selfCollide>true</selfCollide>
  </gazebo>
  
  <gazebo reference="link_4">
  	<selfCollide>true</selfCollide>
  </gazebo>
  
  <gazebo reference="link_5">
  	<selfCollide>true</selfCollide>
  	
  </gazebo>

</robot>
