<?xml version="1.0" encoding="utf-8"?>
<!-- This URDF was automatically created by SolidWorks to URDF Exporter! Originally created by Stephen Brawner (brawner@gmail.com) 
     Commit Version: 1.6.0-4-g7f85cfe  Build Version: 1.6.7995.38578
     For more information, please see http://wiki.ros.org/sw_urdf_exporter -->
<robot
  name="full_robot_arm_urdf">
  
  <link name="world"/>
  
  <link
    name="base_link">
    <inertial>
      <origin
        xyz="-0.00066697 -7.2956E-05 0.11391"
        rpy="0 0 0" />
      <mass
        value="1.2708" />
      <inertia
        ixx="0.0025837"
        ixy="-1.2489E-07"
        ixz="-3.2925E-07"
        iyy="0.0025874"
        iyz="-4.1069E-08"
        izz="0.0043243" />
    </inertial>
    <visual>
      <origin
        xyz="0 0 0"
        rpy="0 0 0" />
      <geometry>
        <mesh
          filename="package://full_robot_arm_urdf/meshes/base_link.STL" />
      </geometry>
      <material
        name="">
        <color
          rgba="0.75294 0.75294 0.75294 1" />
      </material>
    </visual>
    <collision>
      <origin
        xyz="0 0 0"
        rpy="0 0 0" />
      <geometry>
        <mesh
          filename="package://full_robot_arm_urdf/meshes/base_link.STL" />
      </geometry>
    </collision>
  </link>
  
  <joint name="base_joint" type="fixed">
  	<parent link="world"/>
  	<child link="base_link"/>
  	<origin rpy="0 0 0" xyz="0.0 0.0 0.25"/>
  </joint>
  
  <link
    name="link_1">
    <inertial>
      <origin
        xyz="0.034889 0.0045793 0.046707"
        rpy="0 0 0" />
      <mass
        value="0.64188" />
      <inertia
        ixx="0.00046554"
        ixy="-2.0334E-05"
        ixz="2.9258E-05"
        iyy="0.00062637"
        iyz="3.9809E-06"
        izz="0.0006173" />
    </inertial>
    <visual>
      <origin
        xyz="0 0 0"
        rpy="0 0 0" />
      <geometry>
        <mesh
          filename="package://full_robot_arm_urdf/meshes/link_1.STL" />
      </geometry>
      <material
        name="">
        <color
          rgba="0.79216 0.81961 0.93333 1" />
      </material>
    </visual>
    <collision>
      <origin
        xyz="0 0 0"
        rpy="0 0 0" />
      <geometry>
        <mesh
          filename="package://full_robot_arm_urdf/meshes/link_1.STL" />
      </geometry>
    </collision>
  </link>
  <joint
    name="joint_1"
    type="revolute">
    <origin
      xyz="0 0 0.15678"
      rpy="0 0 0" />
    <parent
      link="base_link" />
    <child
      link="link_1" />
    <axis
      xyz="0 0 1" />
    <limit
      lower="-3.142"
      upper="3.142"
      effort="28.35"
      velocity="5.24" />
  </joint>
  <link
    name="link_2">
    <inertial>
      <origin
        xyz="0.001209 0.0061315 0.17443"
        rpy="0 0 0" />
      <mass
        value="0.39695" />
      <inertia
        ixx="0.0020155"
        ixy="5.8977E-06"
        ixz="-4.807E-07"
        iyy="0.0019726"
        iyz="-1.0537E-07"
        izz="0.0001469" />
    </inertial>
    <visual>
      <origin
        xyz="0 0 0"
        rpy="0 0 0" />
      <geometry>
        <mesh
          filename="package://full_robot_arm_urdf/meshes/link_2.STL" />
      </geometry>
      <material
        name="">
        <color
          rgba="0.75294 0.75294 0.75294 1" />
      </material>
    </visual>
    <collision>
      <origin
        xyz="0 0 0"
        rpy="0 0 0" />
      <geometry>
        <mesh
          filename="package://full_robot_arm_urdf/meshes/link_2.STL" />
      </geometry>
    </collision>
  </link>
  <joint
    name="joint_2"
    type="revolute">
    <origin
      xyz="0.00010358 1.3092E-05 0.0737"
      rpy="0 0 0" />
    <parent
      link="link_1" />
    <child
      link="link_2" />
    <axis
      xyz="-0.12539 0.99211 0" />
    <limit
      lower="-1.57"
      upper="1.57"
      effort="28.35"
      velocity="5.24" />
  </joint>
  <link
    name="link_3">
    <inertial>
      <origin
        xyz="-0.12054 -0.010213 -5.7652E-05"
        rpy="0 0 0" />
      <mass
        value="0.27119" />
      <inertia
        ixx="9.092E-05"
        ixy="-0.00014756"
        ixz="-2.1812E-08"
        iyy="0.0012395"
        iyz="3.2219E-07"
        izz="0.0012535" />
    </inertial>
    <visual>
      <origin
        xyz="0 0 0"
        rpy="0 0 0" />
      <geometry>
        <mesh
          filename="package://full_robot_arm_urdf/meshes/link_3.STL" />
      </geometry>
      <material
        name="">
        <color
          rgba="0.75294 0.75294 0.75294 1" />
      </material>
    </visual>
    <collision>
      <origin
        xyz="0 0 0"
        rpy="0 0 0" />
      <geometry>
        <mesh
          filename="package://full_robot_arm_urdf/meshes/link_3.STL" />
      </geometry>
    </collision>
  </link>
  <joint
    name="joint_3"
    type="revolute">
    <origin
      xyz="0 0 0.4064"
      rpy="0 0 0" />
    <parent
      link="link_2" />
    <child
      link="link_3" />
    <axis
      xyz="0.12539 -0.99211 0" />
    <limit
      lower="-1"
      upper="3.14"
      effort="7.85"
      velocity="6.54" />
  </joint>
  <link
    name="link_4">
    <inertial>
      <origin
        xyz="0.00069115 -0.0033768 0.028865"
        rpy="0 0 0" />
      <mass
        value="0.18732" />
      <inertia
        ixx="0.00013117"
        ixy="3.8256E-06"
        ixz="4.7999E-09"
        iyy="0.00010591"
        iyz="-1.726E-08"
        izz="0.00013344" />
    </inertial>
    <visual>
      <origin
        xyz="0 0 0"
        rpy="0 0 0" />
      <geometry>
        <mesh
          filename="package://full_robot_arm_urdf/meshes/link_4.STL" />
      </geometry>
      <material
        name="">
        <color
          rgba="0.75294 0.75294 0.75294 1" />
      </material>
    </visual>
    <collision>
      <origin
        xyz="0 0 0"
        rpy="0 0 0" />
      <geometry>
        <mesh
          filename="package://full_robot_arm_urdf/meshes/link_4.STL" />
      </geometry>
    </collision>
  </link>
  <joint
    name="joint_4"
    type="revolute">
    <origin
      xyz="-0.34841 -0.039718 0"
      rpy="0 0 0" />
    <parent
      link="link_3" />
    <child
      link="link_4" />
    <axis
      xyz="0 0 0" />
    <limit
      lower="-3.14"
      upper="0"
      effort="2.45"
      velocity="8.08" />
  </joint>
  <link
    name="link_5">
    <inertial>
      <origin
        xyz="0.01243 0.0096828 0.039689"
        rpy="0 0 0" />
      <mass
        value="0.46291" />
      <inertia
        ixx="0.00017927"
        ixy="-3.8628E-06"
        ixz="-6.3124E-07"
        iyy="0.00018187"
        iyz="-5.9481E-08"
        izz="0.00028502" />
    </inertial>
    <visual>
      <origin
        xyz="0 0 0"
        rpy="0 0 0" />
      <geometry>
        <mesh
          filename="package://full_robot_arm_urdf/meshes/link_5.STL" />
      </geometry>
      <material
        name="">
        <color
          rgba="0.75294 0.75294 0.75294 1" />
      </material>
    </visual>
    <collision>
      <origin
        xyz="0 0 0"
        rpy="0 0 0" />
      <geometry>
        <mesh
          filename="package://full_robot_arm_urdf/meshes/link_5.STL" />
      </geometry>
    </collision>
  </link>
  <joint
    name="joint_5"
    type="revolute">
    <origin
      xyz="0 0 0.077198"
      rpy="0 0 0" />
    <parent
      link="link_4" />
    <child
      link="link_5" />
    <axis
      xyz="0 0 -1" />
    <limit
      lower="-3.14"
      upper="3.14"
      effort="2.45"
      velocity="8.08" />
  </joint>
  <link
    name="ee_thumb_prox">
    <inertial>
      <origin
        xyz="0.00036374 0.018484 -0.00083701"
        rpy="0 0 0" />
      <mass
        value="0.014062" />
      <inertia
        ixx="2.6604E-06"
        ixy="-6.034E-08"
        ixz="4.9348E-09"
        iyy="6.7376E-07"
        iyz="1.1889E-07"
        izz="2.319E-06" />
    </inertial>
    <visual>
      <origin
        xyz="0 0 0"
        rpy="0 0 0" />
      <geometry>
        <mesh
          filename="package://full_robot_arm_urdf/meshes/ee_thumb_prox.STL" />
      </geometry>
      <material
        name="">
        <color
          rgba="0.75294 0.75294 0.75294 1" />
      </material>
    </visual>
    <collision>
      <origin
        xyz="0 0 0"
        rpy="0 0 0" />
      <geometry>
        <mesh
          filename="package://full_robot_arm_urdf/meshes/ee_thumb_prox.STL" />
      </geometry>
    </collision>
  </link>
  <joint
    name="ee_thumb_prox_joint"
    type="revolute">
    <origin
      xyz="0.044583 0.0062919 0.080425"
      rpy="0.7854 0 -1.4639" />
    <parent
      link="link_5" />
    <child
      link="ee_thumb_prox" />
    <axis
      xyz="0 0 0" />
    <limit
      lower="0"
      upper="1.57"
      effort="2.45"
      velocity="8.08" />
  </joint>
  <link
    name="ee_thumb_dist">
    <inertial>
      <origin
        xyz="-2.0368E-05 0.018518 -0.00074741"
        rpy="0 0 0" />
      <mass
        value="0.012049" />
      <inertia
        ixx="1.1236E-06"
        ixy="5.5608E-09"
        ixz="-1.7293E-09"
        iyy="7.1961E-07"
        iyz="1.8903E-09"
        izz="8.9454E-07" />
    </inertial>
    <visual>
      <origin
        xyz="0 0 0"
        rpy="0 0 0" />
      <geometry>
        <mesh
          filename="package://full_robot_arm_urdf/meshes/ee_thumb_dist.STL" />
      </geometry>
      <material
        name="">
        <color
          rgba="0.75294 0.75294 0.75294 1" />
      </material>
    </visual>
    <collision>
      <origin
        xyz="0 0 0"
        rpy="0 0 0" />
      <geometry>
        <mesh
          filename="package://full_robot_arm_urdf/meshes/ee_thumb_dist.STL" />
      </geometry>
    </collision>
  </link>
  <joint
    name="ee_thumb_dist_joint"
    type="revolute">
    <origin
      xyz="0 0.05 0"
      rpy="0 0 0" />
    <parent
      link="ee_thumb_prox" />
    <child
      link="ee_thumb_dist" />
    <axis
      xyz="0 0 0" />
    <limit
      lower="0"
      upper="1.57"
      effort="2.45"
      velocity="8.08" />
  </joint>
  <link
    name="ee_finger1_roll">
    <inertial>
      <origin
        xyz="-0.0031118 -0.019461 -0.0029452"
        rpy="0 0 0" />
      <mass
        value="0.025934" />
      <inertia
        ixx="1.756E-06"
        ixy="2.0595E-07"
        ixz="-2.543E-07"
        iyy="2.5253E-06"
        iyz="8.1456E-08"
        izz="2.1011E-06" />
    </inertial>
    <visual>
      <origin
        xyz="0 0 0"
        rpy="0 0 0" />
      <geometry>
        <mesh
          filename="package://full_robot_arm_urdf/meshes/ee_finger1_roll.STL" />
      </geometry>
      <material
        name="">
        <color
          rgba="0.75294 0.75294 0.75294 1" />
      </material>
    </visual>
    <collision>
      <origin
        xyz="0 0 0"
        rpy="0 0 0" />
      <geometry>
        <mesh
          filename="package://full_robot_arm_urdf/meshes/ee_finger1_roll.STL" />
      </geometry>
    </collision>
  </link>
  <joint
    name="ee_finger1_roll_joint"
    type="revolute">
    <origin
      xyz="-0.02203 -0.029016 0.082425"
      rpy="1.5708 0 1.6777" />
    <parent
      link="link_5" />
    <child
      link="ee_finger1_roll" />
    <axis
      xyz="0 0 0" />
    <limit
      lower="-3.14"
      upper="3.14"
      effort="2.45"
      velocity="8.08" />
  </joint>
  <link
    name="ee_finger1_prox">
    <inertial>
      <origin
        xyz="-0.0099575 0.016221 0.0017359"
        rpy="0 0 0" />
      <mass
        value="0.014979" />
      <inertia
        ixx="2.0553E-06"
        ixy="8.5154E-07"
        ixz="-4.8998E-08"
        iyy="1.2223E-06"
        iyz="-1.8872E-07"
        izz="2.4204E-06" />
    </inertial>
    <visual>
      <origin
        xyz="0 0 0"
        rpy="0 0 0" />
      <geometry>
        <mesh
          filename="package://full_robot_arm_urdf/meshes/ee_finger1_prox.STL" />
      </geometry>
      <material
        name="">
        <color
          rgba="0.75294 0.75294 0.75294 1" />
      </material>
    </visual>
    <collision>
      <origin
        xyz="0 0 0"
        rpy="0 0 0" />
      <geometry>
        <mesh
          filename="package://full_robot_arm_urdf/meshes/ee_finger1_prox.STL" />
      </geometry>
    </collision>
  </link>
  <joint
    name="ee_finger1_prox_joint"
    type="revolute">
    <origin
      xyz="0 0 0"
      rpy="-0.7854 0 0" />
    <parent
      link="ee_finger1_roll" />
    <child
      link="ee_finger1_prox" />
    <axis
      xyz="0 0 0" />
    <limit
      lower="0"
      upper="1.57"
      effort="2.45"
      velocity="8.08" />
  </joint>
  <link
    name="ee_finger1_dist">
    <inertial>
      <origin
        xyz="-0.035468 0.0072359 0.0095347"
        rpy="0 0 0" />
      <mass
        value="0.01344" />
      <inertia
        ixx="9.8068E-07"
        ixy="1.3911E-07"
        ixz="-4.7724E-08"
        iyy="8.721E-07"
        iyz="-7.0388E-08"
        izz="9.8856E-07" />
    </inertial>
    <visual>
      <origin
        xyz="0 0 0"
        rpy="0 0 0" />
      <geometry>
        <mesh
          filename="package://full_robot_arm_urdf/meshes/ee_finger1_dist.STL" />
      </geometry>
      <material
        name="">
        <color
          rgba="0.75294 0.75294 0.75294 1" />
      </material>
    </visual>
    <collision>
      <origin
        xyz="0 0 0"
        rpy="0 0 0" />
      <geometry>
        <mesh
          filename="package://full_robot_arm_urdf/meshes/ee_finger1_dist.STL" />
      </geometry>
    </collision>
  </link>
  <joint
    name="ee_finger1_dist_joint"
    type="revolute">
    <origin
      xyz="0 0.05 0"
      rpy="0 0 0" />
    <parent
      link="ee_finger1_prox" />
    <child
      link="ee_finger1_dist" />
    <axis
      xyz="0 0 0" />
    <limit
      lower="0"
      upper="1.57"
      effort="2.45"
      velocity="8.08" />
  </joint>
  <link
    name="ee_finger2_roll">
    <inertial>
      <origin
        xyz="-0.00044525 -0.019457 0.0042178"
        rpy="0 0 0" />
      <mass
        value="0.025934" />
      <inertia
        ixx="2.1487E-06"
        ixy="1.0432E-07"
        ixz="2.1449E-07"
        iyy="2.5253E-06"
        iyz="-1.9524E-07"
        izz="1.7085E-06" />
    </inertial>
    <visual>
      <origin
        xyz="0 0 0"
        rpy="0 0 0" />
      <geometry>
        <mesh
          filename="package://full_robot_arm_urdf/meshes/ee_finger2_roll.STL" />
      </geometry>
      <material
        name="">
        <color
          rgba="0.75294 0.75294 0.75294 1" />
      </material>
    </visual>
    <collision>
      <origin
        xyz="0 0 0"
        rpy="0 0 0" />
      <geometry>
        <mesh
          filename="package://full_robot_arm_urdf/meshes/ee_finger2_roll.STL" />
      </geometry>
    </collision>
  </link>
  <joint
    name="ee_finger2_roll_joint"
    type="revolute">
    <origin
      xyz="-0.028004 0.026665 0.082425"
      rpy="1.5708 0 -2.162" />
    <parent
      link="link_5" />
    <child
      link="ee_finger2_roll" />
    <axis
      xyz="0 0 0" />
    <limit
      lower="-3.14"
      upper="3.14"
      effort="2.45"
      velocity="8.08" />
  </joint>
  <link
    name="ee_finger2_prox">
    <inertial>
      <origin
        xyz="-0.00081104 0.018755 0.00091924"
        rpy="0 0 0" />
      <mass
        value="0.01482" />
      <inertia
        ixx="2.6619E-06"
        ixy="8.2095E-08"
        ixz="2.3497E-08"
        iyy="6.8817E-07"
        iyz="-9.873E-08"
        izz="2.3408E-06" />
    </inertial>
    <visual>
      <origin
        xyz="0 0 0"
        rpy="0 0 0" />
      <geometry>
        <mesh
          filename="package://full_robot_arm_urdf/meshes/ee_finger2_prox.STL" />
      </geometry>
      <material
        name="">
        <color
          rgba="0.75294 0.75294 0.75294 1" />
      </material>
    </visual>
    <collision>
      <origin
        xyz="0 0 0"
        rpy="0 0 0" />
      <geometry>
        <mesh
          filename="package://full_robot_arm_urdf/meshes/ee_finger2_prox.STL" />
      </geometry>
    </collision>
  </link>
  <joint
    name="ee_finger2_prox_joint"
    type="revolute">
    <origin
      xyz="0 0 0"
      rpy="0.7854 0 0" />
    <parent
      link="ee_finger2_roll" />
    <child
      link="ee_finger2_prox" />
    <axis
      xyz="0 0 0" />
    <limit
      lower="0"
      upper="1.57"
      effort="2.45"
      velocity="8.08" />
  </joint>
  <link
    name="ee_finger2_dist">
    <inertial>
      <origin
        xyz="-0.0048626 0.017613 0.00018819"
        rpy="0 0 0" />
      <mass
        value="0.013599" />
      <inertia
        ixx="1.1232E-06"
        ixy="2.933E-08"
        ixz="1.3291E-08"
        iyy="7.7622E-07"
        iyz="3.9678E-09"
        izz="9.4904E-07" />
    </inertial>
    <visual>
      <origin
        xyz="0 0 0"
        rpy="0 0 0" />
      <geometry>
        <mesh
          filename="package://full_robot_arm_urdf/meshes/ee_finger2_dist.STL" />
      </geometry>
      <material
        name="">
        <color
          rgba="0.75294 0.75294 0.75294 1" />
      </material>
    </visual>
    <collision>
      <origin
        xyz="0 0 0"
        rpy="0 0 0" />
      <geometry>
        <mesh
          filename="package://full_robot_arm_urdf/meshes/ee_finger2_dist.STL" />
      </geometry>
    </collision>
  </link>
  <joint
    name="ee_finger2_dist_joint"
    type="revolute">
    <origin
      xyz="0 0.05 0"
      rpy="0 0 0" />
    <parent
      link="ee_finger2_prox" />
    <child
      link="ee_finger2_dist" />
    <axis
      xyz="0 0 0" />
    <limit
      lower="0"
      upper="1.57"
      effort="2.45"
      velocity="8.08" />
  </joint>
  
  <transmission name="link_1_trans">
  	<type>transmission_interface/SimpleTransmission</type>
  	<joint name="joint_1">
  		<hardwareInterface>hardware_interface/PositionJointInterface</hardwareInterface>
  	</joint>
  	<actuator name="link_1_motor">
  		<hardwareInterface>hardware_interface/PositionJointInterface</hardwareInterface>
  		<mechanicalReduction>1</mechanicalReduction>
  	</actuator>
  </transmission>
  
  <transmission name="link_2_trans">
  	<type>transmission_interface/SimpleTransmission</type>
  	<joint name="joint_2">
  		<hardwareInterface>hardware_interface/PositionJointInterface</hardwareInterface>
  	</joint>
  	<actuator name="link_2_motor">
  		<hardwareInterface>hardware_interface/PositionJointInterface</hardwareInterface>
  		<mechanicalReduction>1</mechanicalReduction>
  	</actuator>
  </transmission>
  
  <transmission name="link_3_trans">
  	<type>transmission_interface/SimpleTransmission</type>
  	<joint name="joint_3">
  		<hardwareInterface>hardware_interface/PositionJointInterface</hardwareInterface>
  	</joint>
  	<actuator name="link_3_motor">
  		<hardwareInterface>hardware_interface/PositionJointInterface</hardwareInterface>
  		<mechanicalReduction>1</mechanicalReduction>
  	</actuator>
  </transmission>
  
  <transmission name="link_4_trans">
  	<type>transmission_interface/SimpleTransmission</type>
  	<joint name="joint_4">
  		<hardwareInterface>hardware_interface/PositionJointInterface</hardwareInterface>
  	</joint>
  	<actuator name="link_4_motor">
  		<hardwareInterface>hardware_interface/PositionJointInterface</hardwareInterface>
  		<mechanicalReduction>1</mechanicalReduction>
  	</actuator>
  </transmission>
  
  <transmission name="link_5_trans">
  	<type>transmission_interface/SimpleTransmission</type>
  	<joint name="joint_5">
  		<hardwareInterface>hardware_interface/PositionJointInterface</hardwareInterface>
  	</joint>
  	<actuator name="link_5_motor">
  		<hardwareInterface>hardware_interface/PositionJointInterface</hardwareInterface>
  		<mechanicalReduction>1</mechanicalReduction>
  	</actuator>
  </transmission>
  
  <transmission name="ee_thumb_prox_trans">
  	<type>transmission_interface/SimpleTransmission</type>
  	<joint name="ee_thumb_prox_joint">
  		<hardwareInterface>hardware_interface/PositionJointInterface</hardwareInterface>
  	</joint>
  	<actuator name="ee_thumb_prox_joint_motor">
  		<hardwareInterface>hardware_interface/PositionJointInterface</hardwareInterface>
  		<mechanicalReduction>1</mechanicalReduction>
  	</actuator>
  </transmission>
  
  <transmission name="ee_thumb_dist_trans">
  	<type>transmission_interface/SimpleTransmission</type>
  	<joint name="ee_thumb_dist_joint">
  		<hardwareInterface>hardware_interface/PositionJointInterface</hardwareInterface>
  	</joint>
  	<actuator name="ee_thumb_dist_joint_motor">
  		<hardwareInterface>hardware_interface/PositionJointInterface</hardwareInterface>
  		<mechanicalReduction>1</mechanicalReduction>
  	</actuator>
  </transmission>
  
  <transmission name="ee_finger1_roll_trans">
  	<type>transmission_interface/SimpleTransmission</type>
  	<joint name="ee_finger1_roll_joint">
  		<hardwareInterface>hardware_interface/PositionJointInterface</hardwareInterface>
  	</joint>
  	<actuator name="ee_finger1_roll_joint_motor">
  		<hardwareInterface>hardware_interface/PositionJointInterface</hardwareInterface>
  		<mechanicalReduction>1</mechanicalReduction>
  	</actuator>
  </transmission>
  
  <transmission name="ee_finger1_prox_trans">
  	<type>transmission_interface/SimpleTransmission</type>
  	<joint name="ee_finger1_prox_joint">
  		<hardwareInterface>hardware_interface/PositionJointInterface</hardwareInterface>
  	</joint>
  	<actuator name="ee_finger1_prox_joint_motor">
  		<hardwareInterface>hardware_interface/PositionJointInterface</hardwareInterface>
  		<mechanicalReduction>1</mechanicalReduction>
  	</actuator>
  </transmission>
  
  <transmission name="ee_finger1_dist_trans">
  	<type>transmission_interface/SimpleTransmission</type>
  	<joint name="ee_finger1_dist_joint">
  		<hardwareInterface>hardware_interface/PositionJointInterface</hardwareInterface>
  	</joint>
  	<actuator name="ee_finger1_dist_joint_motor">
  		<hardwareInterface>hardware_interface/PositionJointInterface</hardwareInterface>
  		<mechanicalReduction>1</mechanicalReduction>
  	</actuator>
  </transmission>
  
  <transmission name="ee_finger2_roll_trans">
  	<type>transmission_interface/SimpleTransmission</type>
  	<joint name="ee_finger2_roll_joint">
  		<hardwareInterface>hardware_interface/PositionJointInterface</hardwareInterface>
  	</joint>
  	<actuator name="ee_finger2_roll_joint_motor">
  		<hardwareInterface>hardware_interface/PositionJointInterface</hardwareInterface>
  		<mechanicalReduction>1</mechanicalReduction>
  	</actuator>
  </transmission>
  
  <transmission name="ee_finger2_prox_trans">
  	<type>transmission_interface/SimpleTransmission</type>
  	<joint name="ee_finger2_prox_joint">
  		<hardwareInterface>hardware_interface/PositionJointInterface</hardwareInterface>
  	</joint>
  	<actuator name="ee_finger2_prox_joint_motor">
  		<hardwareInterface>hardware_interface/PositionJointInterface</hardwareInterface>
  		<mechanicalReduction>1</mechanicalReduction>
  	</actuator>
  </transmission>
  
  <transmission name="ee_finger2_dist_trans">
  	<type>transmission_interface/SimpleTransmission</type>
  	<joint name="ee_finger2_dist_joint">
  		<hardwareInterface>hardware_interface/PositionJointInterface</hardwareInterface>
  	</joint>
  	<actuator name="ee_finger2_dist_joint_motor">
  		<hardwareInterface>hardware_interface/PositionJointInterface</hardwareInterface>
  		<mechanicalReduction>1</mechanicalReduction>
  	</actuator>
  </transmission>
  
  <gazebo>
  	<plugin name="control" filename="libgazebo_ros_control.so">
  		<robotNamespace>/</robotNamespace>
  	</plugin>
  </gazebo>
  
  <gazebo reference="link_1">
  	<selfCollide>true</selfCollide>
  </gazebo>
  
  <gazebo reference="link_2">
  	<selfCollide>true</selfCollide>
  </gazebo>
  
  <gazebo reference="link_3">
  	<selfCollide>true</selfCollide>
  </gazebo>
  
  <gazebo reference="link_4">
  	<selfCollide>true</selfCollide>
  </gazebo>
  
  <gazebo reference="link_5">
  	<selfCollide>true</selfCollide>
  </gazebo>
  
  <gazebo reference="ee_thumb_prox">
  	<selfCollide>true</selfCollide>
  </gazebo>
  
  <gazebo reference="ee_thumb_dist">
  	<selfCollide>true</selfCollide>
  </gazebo>
  
  <gazebo reference="ee_finger1_roll">
  	<selfCollide>true</selfCollide>
  </gazebo>
  
  <gazebo reference="ee_finger1_prox">
  	<selfCollide>true</selfCollide>
  </gazebo>
  
  <gazebo reference="ee_finger1_dist">
  	<selfCollide>true</selfCollide>
  </gazebo>
  
  <gazebo reference="ee_finger2_roll">
  	<selfCollide>true</selfCollide>
  </gazebo>
  
  <gazebo reference="ee_finger2_prox">
  	<selfCollide>true</selfCollide>
  </gazebo>
  
  <gazebo reference="ee_finger2_dist">
  	<selfCollide>true</selfCollide>
  </gazebo>
  
</robot>
