<?xml version="1.0" encoding="utf-8"?>
<!-- This URDF was automatically created by SolidWorks to URDF Exporter! Originally created by Stephen Brawner (brawner@gmail.com) 
     Commit Version: 1.6.0-4-g7f85cfe  Build Version: 1.6.7995.38578
     For more information, please see http://wiki.ros.org/sw_urdf_exporter -->
<robot
  name="Arm Assembly URDF.SLDASM">
  <link
    name="base_link">
    <inertial>
      <origin
        xyz="0.1463 0.022736 0.078618"
        rpy="0 0 0" />
      <mass
        value="2.2785" />
      <inertia
        ixx="0.0038044"
        ixy="-0.00020619"
        ixz="0.00015099"
        iyy="0.0048644"
        iyz="1.9405E-05"
        izz="0.0072065" />
    </inertial>
    <visual>
      <origin
        xyz="0 0 0"
        rpy="0 0 0" />
      <geometry>
        <mesh
          filename="package://Arm Assembly URDF.SLDASM/meshes/base_link.STL" />
      </geometry>
      <material
        name="">
        <color
          rgba="0.75294 0.75294 0.75294 1" />
      </material>
    </visual>
    <collision>
      <origin
        xyz="0 0 0"
        rpy="0 0 0" />
      <geometry>
        <mesh
          filename="package://Arm Assembly URDF.SLDASM/meshes/base_link.STL" />
      </geometry>
    </collision>
  </link>
  <link
    name="link_1">
    <inertial>
      <origin
        xyz="0.024975 0.040357 -0.024788"
        rpy="0 0 0" />
      <mass
        value="0.64188" />
      <inertia
        ixx="0.00054422"
        ixy="2.0857E-05"
        ixz="8.2925E-05"
        iyy="0.0006173"
        iyz="-2.0897E-05"
        izz="0.00054768" />
    </inertial>
    <visual>
      <origin
        xyz="0 0 0"
        rpy="0 0 0" />
      <geometry>
        <mesh
          filename="package://Arm Assembly URDF.SLDASM/meshes/link_1.STL" />
      </geometry>
      <material
        name="">
        <color
          rgba="0.75294 0.75294 0.75294 1" />
      </material>
    </visual>
    <collision>
      <origin
        xyz="0 0 0"
        rpy="0 0 0" />
      <geometry>
        <mesh
          filename="package://Arm Assembly URDF.SLDASM/meshes/link_1.STL" />
      </geometry>
    </collision>
  </link>
  <joint
    name="joint_1"
    type="revolute">
    <origin
      xyz="0 0 0.16313"
      rpy="1.5708 0 -0.65112" />
    <parent
      link="base_link" />
    <child
      link="link_1" />
    <axis
      xyz="0 1 0" />
    <limit
      lower="-1.57"
      upper="1.57"
      effort="28.35"
      velocity="5.24" />
  </joint>
  <link
    name="link_2">
    <inertial>
      <origin
        xyz="0.17391 0.023451 -0.048747"
        rpy="0 0 0" />
      <mass
        value="0.39467" />
      <inertia
        ixx="0.00014684"
        ixy="4.9101E-07"
        ixz="4.3664E-08"
        iyy="0.0020162"
        iyz="3.7294E-07"
        izz="0.0019717" />
    </inertial>
    <visual>
      <origin
        xyz="0 0 0"
        rpy="0 0 0" />
      <geometry>
        <mesh
          filename="package://Arm Assembly URDF.SLDASM/meshes/link_2.STL" />
      </geometry>
      <material
        name="">
        <color
          rgba="0.75294 0.75294 0.75294 1" />
      </material>
    </visual>
    <collision>
      <origin
        xyz="0 0 0"
        rpy="0 0 0" />
      <geometry>
        <mesh
          filename="package://Arm Assembly URDF.SLDASM/meshes/link_2.STL" />
      </geometry>
    </collision>
  </link>
  <joint
    name="joint_2"
    type="revolute">
    <origin
      xyz="0.048155 0.06735 0.012605"
      rpy="0.77684 0 1.5708" />
    <parent
      link="link_1" />
    <child
      link="link_2" />
    <axis
      xyz="0 0 -1" />
    <limit
      lower="-1.57"
      upper="1.57"
      effort="28.35"
      velocity="5.24" />
  </joint>
  <link
    name="link_3">
    <inertial>
      <origin
        xyz="0.11503 0.025536 -0.029769"
        rpy="0 0 0" />
      <mass
        value="0.25926" />
      <inertia
        ixx="6.9599E-05"
        ixy="1.1789E-08"
        ixz="2.6815E-08"
        iyy="0.0012488"
        iyz="-5.9275E-08"
        izz="0.0012534" />
    </inertial>
    <visual>
      <origin
        xyz="0 0 0"
        rpy="0 0 0" />
      <geometry>
        <mesh
          filename="package://Arm Assembly URDF.SLDASM/meshes/link_3.STL" />
      </geometry>
      <material
        name="">
        <color
          rgba="0.75294 0.75294 0.75294 1" />
      </material>
    </visual>
    <collision>
      <origin
        xyz="0 0 0"
        rpy="0 0 0" />
      <geometry>
        <mesh
          filename="package://Arm Assembly URDF.SLDASM/meshes/link_3.STL" />
      </geometry>
    </collision>
  </link>
  <joint
    name="joint_3"
    type="revolute">
    <origin
      xyz="0.4318 0.0254 -0.016751"
      rpy="0 0 1.5708" />
    <parent
      link="link_2" />
    <child
      link="link_3" />
    <axis
      xyz="0 0 -1" />
    <limit
      lower="-1"
      upper="3.14"
      effort="7.85"
      velocity="6.54" />
  </joint>
  <link
    name="link_4">
    <inertial>
      <origin
        xyz="0.0034368 0.048333 -0.025392"
        rpy="0 0 0" />
      <mass
        value="0.18732" />
      <inertia
        ixx="0.00010535"
        ixy="-1.7725E-08"
        ixz="-5.6239E-07"
        iyy="0.00013344"
        iyz="-2.5978E-09"
        izz="0.00013173" />
    </inertial>
    <visual>
      <origin
        xyz="0 0 0"
        rpy="0 0 0" />
      <geometry>
        <mesh
          filename="package://Arm Assembly URDF.SLDASM/meshes/link_4.STL" />
      </geometry>
      <material
        name="">
        <color
          rgba="0.75294 0.75294 0.75294 1" />
      </material>
    </visual>
    <collision>
      <origin
        xyz="0 0 0"
        rpy="0 0 0" />
      <geometry>
        <mesh
          filename="package://Arm Assembly URDF.SLDASM/meshes/link_4.STL" />
      </geometry>
    </collision>
  </link>
  <joint
    name="joint_4"
    type="revolute">
    <origin
      xyz="0.32499 -0.051798 -0.03028"
      rpy="3.1416 -1.5708 0" />
    <parent
      link="link_3" />
    <child
      link="link_4" />
    <axis
      xyz="-1 0 0" />
    <limit
      lower="-3.14"
      upper="0"
      effort="2.45"
      velocity="8.08" />
  </joint>
  <link
    name="link_5">
    <inertial>
      <origin
        xyz="-2.3525E-09 0.0038409 4.4635E-09"
        rpy="0 0 0" />
      <mass
        value="0.0035244" />
      <inertia
        ixx="2.3045E-07"
        ixy="5.3295E-13"
        ixz="5.8374E-12"
        iyy="3.9951E-07"
        iyz="4.126E-13"
        izz="2.3046E-07" />
    </inertial>
    <visual>
      <origin
        xyz="0 0 0"
        rpy="0 0 0" />
      <geometry>
        <mesh
          filename="package://Arm Assembly URDF.SLDASM/meshes/link_5.STL" />
      </geometry>
      <material
        name="">
        <color
          rgba="0.75294 0.75294 0.75294 1" />
      </material>
    </visual>
    <collision>
      <origin
        xyz="0 0 0"
        rpy="0 0 0" />
      <geometry>
        <mesh
          filename="package://Arm Assembly URDF.SLDASM/meshes/link_5.STL" />
      </geometry>
    </collision>
  </link>
  <joint
    name="joint_5"
    type="revolute">
    <origin
      xyz="0 -0.011425 -0.025654"
      rpy="-3.1416 -0.052114 -3.1416" />
    <parent
      link="link_4" />
    <child
      link="link_5" />
    <axis
      xyz="0 1 0" />
    <limit
      lower="-3.14"
      upper="3.14"
      effort="2.45"
      velocity="8.08" />
  </joint>
</robot>